Internal Server Error: /questions/
Traceback (most recent call last):
  File "/home/adam/projects/virtualenvs/py352/lib/python3.5/site-packages/django/core/handlers/exception.py", line 34, in inner
    response = get_response(request)
  File "/home/adam/projects/virtualenvs/py352/lib/python3.5/site-packages/django/core/handlers/base.py", line 111, in _get_response
    resolver_match = resolver.resolve(request.path_info)
  File "/home/adam/projects/virtualenvs/py352/lib/python3.5/site-packages/django/urls/resolvers.py", line 491, in resolve
    for pattern in self.url_patterns:
  File "/home/adam/projects/virtualenvs/py352/lib/python3.5/site-packages/django/utils/functional.py", line 37, in __get__
    res = instance.__dict__[self.name] = self.func(instance)
  File "/home/adam/projects/virtualenvs/py352/lib/python3.5/site-packages/django/urls/resolvers.py", line 533, in url_patterns
    patterns = getattr(self.urlconf_module, "urlpatterns", self.urlconf_module)
  File "/home/adam/projects/virtualenvs/py352/lib/python3.5/site-packages/django/utils/functional.py", line 37, in __get__
    res = instance.__dict__[self.name] = self.func(instance)
  File "/home/adam/projects/virtualenvs/py352/lib/python3.5/site-packages/django/urls/resolvers.py", line 526, in urlconf_module
    return import_module(self.urlconf_name)
  File "/usr/lib/python3.5/importlib/__init__.py", line 126, in import_module
    return _bootstrap._gcd_import(name[level:], package, level)
  File "<frozen importlib._bootstrap>", line 986, in _gcd_import
  File "<frozen importlib._bootstrap>", line 969, in _find_and_load
  File "<frozen importlib._bootstrap>", line 958, in _find_and_load_unlocked
  File "<frozen importlib._bootstrap>", line 673, in _load_unlocked
  File "<frozen importlib._bootstrap_external>", line 665, in exec_module
  File "<frozen importlib._bootstrap>", line 222, in _call_with_frames_removed
  File "./djaler/urls.py", line 23, in <module>
    path('questions/', include('app_questions.urls')),
  File "/home/adam/projects/virtualenvs/py352/lib/python3.5/site-packages/django/urls/conf.py", line 34, in include
    urlconf_module = import_module(urlconf_module)
  File "/usr/lib/python3.5/importlib/__init__.py", line 126, in import_module
    return _bootstrap._gcd_import(name[level:], package, level)
  File "<frozen importlib._bootstrap>", line 986, in _gcd_import
  File "<frozen importlib._bootstrap>", line 969, in _find_and_load
  File "<frozen importlib._bootstrap>", line 958, in _find_and_load_unlocked
  File "<frozen importlib._bootstrap>", line 673, in _load_unlocked
  File "<frozen importlib._bootstrap_external>", line 665, in exec_module
  File "<frozen importlib._bootstrap>", line 222, in _call_with_frames_removed
  File "./app_questions/urls.py", line 20, in <module>
    path(r'^(?P<question_slug>[A-Za-z0-9-]+)/$', QuestionPage.as_view(), name='question'),
NameError: name 'QuestionPage' is not defined
[pid: 12032|app: 0|req: 2/2] 127.0.0.1 () {46 vars in 963 bytes} [Wed Oct  3 18:18:48 2018] GET /questions/ => generated 138083 bytes in 54 msecs (HTTP/1.1 500) 4 headers in 130 bytes (1 switches on core 0)
Internal Server Error: /questions/
Traceback (most recent call last):
  File "/home/adam/projects/virtualenvs/py352/lib/python3.5/site-packages/django/core/handlers/exception.py", line 34, in inner
    response = get_response(request)
  File "/home/adam/projects/virtualenvs/py352/lib/python3.5/site-packages/django/core/handlers/base.py", line 111, in _get_response
    resolver_match = resolver.resolve(request.path_info)
  File "/home/adam/projects/virtualenvs/py352/lib/python3.5/site-packages/django/urls/resolvers.py", line 491, in resolve
    for pattern in self.url_patterns:
  File "/home/adam/projects/virtualenvs/py352/lib/python3.5/site-packages/django/utils/functional.py", line 37, in __get__
    res = instance.__dict__[self.name] = self.func(instance)
  File "/home/adam/projects/virtualenvs/py352/lib/python3.5/site-packages/django/urls/resolvers.py", line 533, in url_patterns
    patterns = getattr(self.urlconf_module, "urlpatterns", self.urlconf_module)
  File "/home/adam/projects/virtualenvs/py352/lib/python3.5/site-packages/django/utils/functional.py", line 37, in __get__
    res = instance.__dict__[self.name] = self.func(instance)
  File "/home/adam/projects/virtualenvs/py352/lib/python3.5/site-packages/django/urls/resolvers.py", line 526, in urlconf_module
    return import_module(self.urlconf_name)
  File "/usr/lib/python3.5/importlib/__init__.py", line 126, in import_module
    return _bootstrap._gcd_import(name[level:], package, level)
  File "<frozen importlib._bootstrap>", line 986, in _gcd_import
  File "<frozen importlib._bootstrap>", line 969, in _find_and_load
  File "<frozen importlib._bootstrap>", line 958, in _find_and_load_unlocked
  File "<frozen importlib._bootstrap>", line 673, in _load_unlocked
  File "<frozen importlib._bootstrap_external>", line 665, in exec_module
  File "<frozen importlib._bootstrap>", line 222, in _call_with_frames_removed
  File "./djaler/urls.py", line 23, in <module>
    path('questions/', include('app_questions.urls')),
  File "/home/adam/projects/virtualenvs/py352/lib/python3.5/site-packages/django/urls/conf.py", line 34, in include
    urlconf_module = import_module(urlconf_module)
  File "/usr/lib/python3.5/importlib/__init__.py", line 126, in import_module
    return _bootstrap._gcd_import(name[level:], package, level)
  File "<frozen importlib._bootstrap>", line 986, in _gcd_import
  File "<frozen importlib._bootstrap>", line 969, in _find_and_load
  File "<frozen importlib._bootstrap>", line 958, in _find_and_load_unlocked
  File "<frozen importlib._bootstrap>", line 673, in _load_unlocked
  File "<frozen importlib._bootstrap_external>", line 665, in exec_module
  File "<frozen importlib._bootstrap>", line 222, in _call_with_frames_removed
  File "./app_questions/urls.py", line 20, in <module>
    path(r'^(?P<question_slug>[A-Za-z0-9-]+)/$', QuestionPage.as_view(), name='question'),
NameError: name 'QuestionPage' is not defined
[pid: 12032|app: 0|req: 3/3] 127.0.0.1 () {46 vars in 963 bytes} [Wed Oct  3 18:18:48 2018] GET /questions/ => generated 138083 bytes in 55 msecs (HTTP/1.1 500) 4 headers in 130 bytes (1 switches on core 0)
Internal Server Error: /questions/
Traceback (most recent call last):
  File "/home/adam/projects/virtualenvs/py352/lib/python3.5/site-packages/django/core/handlers/exception.py", line 34, in inner
    response = get_response(request)
  File "/home/adam/projects/virtualenvs/py352/lib/python3.5/site-packages/django/core/handlers/base.py", line 111, in _get_response
    resolver_match = resolver.resolve(request.path_info)
  File "/home/adam/projects/virtualenvs/py352/lib/python3.5/site-packages/django/urls/resolvers.py", line 491, in resolve
    for pattern in self.url_patterns:
  File "/home/adam/projects/virtualenvs/py352/lib/python3.5/site-packages/django/utils/functional.py", line 37, in __get__
    res = instance.__dict__[self.name] = self.func(instance)
  File "/home/adam/projects/virtualenvs/py352/lib/python3.5/site-packages/django/urls/resolvers.py", line 533, in url_patterns
    patterns = getattr(self.urlconf_module, "urlpatterns", self.urlconf_module)
  File "/home/adam/projects/virtualenvs/py352/lib/python3.5/site-packages/django/utils/functional.py", line 37, in __get__
    res = instance.__dict__[self.name] = self.func(instance)
  File "/home/adam/projects/virtualenvs/py352/lib/python3.5/site-packages/django/urls/resolvers.py", line 526, in urlconf_module
    return import_module(self.urlconf_name)
  File "/usr/lib/python3.5/importlib/__init__.py", line 126, in import_module
    return _bootstrap._gcd_import(name[level:], package, level)
  File "<frozen importlib._bootstrap>", line 986, in _gcd_import
  File "<frozen importlib._bootstrap>", line 969, in _find_and_load
  File "<frozen importlib._bootstrap>", line 958, in _find_and_load_unlocked
  File "<frozen importlib._bootstrap>", line 673, in _load_unlocked
  File "<frozen importlib._bootstrap_external>", line 665, in exec_module
  File "<frozen importlib._bootstrap>", line 222, in _call_with_frames_removed
  File "./djaler/urls.py", line 23, in <module>
    path('questions/', include('app_questions.urls')),
  File "/home/adam/projects/virtualenvs/py352/lib/python3.5/site-packages/django/urls/conf.py", line 34, in include
    urlconf_module = import_module(urlconf_module)
  File "/usr/lib/python3.5/importlib/__init__.py", line 126, in import_module
    return _bootstrap._gcd_import(name[level:], package, level)
  File "<frozen importlib._bootstrap>", line 986, in _gcd_import
  File "<frozen importlib._bootstrap>", line 969, in _find_and_load
  File "<frozen importlib._bootstrap>", line 958, in _find_and_load_unlocked
  File "<frozen importlib._bootstrap>", line 673, in _load_unlocked
  File "<frozen importlib._bootstrap_external>", line 665, in exec_module
  File "<frozen importlib._bootstrap>", line 222, in _call_with_frames_removed
  File "./app_questions/urls.py", line 20, in <module>
    path(r'^(?P<question_slug>[A-Za-z0-9-]+)/$', QuestionPage.as_view(), name='question'),
NameError: name 'QuestionPage' is not defined
[pid: 12032|app: 0|req: 4/4] 127.0.0.1 () {46 vars in 963 bytes} [Wed Oct  3 18:18:49 2018] GET /questions/ => generated 138083 bytes in 70 msecs (HTTP/1.1 500) 4 headers in 130 bytes (1 switches on core 0)
Internal Server Error: /
Traceback (most recent call last):
  File "/home/adam/projects/virtualenvs/py352/lib/python3.5/site-packages/django/core/handlers/exception.py", line 34, in inner
    response = get_response(request)
  File "/home/adam/projects/virtualenvs/py352/lib/python3.5/site-packages/django/core/handlers/base.py", line 111, in _get_response
    resolver_match = resolver.resolve(request.path_info)
  File "/home/adam/projects/virtualenvs/py352/lib/python3.5/site-packages/django/urls/resolvers.py", line 491, in resolve
    for pattern in self.url_patterns:
  File "/home/adam/projects/virtualenvs/py352/lib/python3.5/site-packages/django/utils/functional.py", line 37, in __get__
    res = instance.__dict__[self.name] = self.func(instance)
  File "/home/adam/projects/virtualenvs/py352/lib/python3.5/site-packages/django/urls/resolvers.py", line 533, in url_patterns
    patterns = getattr(self.urlconf_module, "urlpatterns", self.urlconf_module)
  File "/home/adam/projects/virtualenvs/py352/lib/python3.5/site-packages/django/utils/functional.py", line 37, in __get__
    res = instance.__dict__[self.name] = self.func(instance)
  File "/home/adam/projects/virtualenvs/py352/lib/python3.5/site-packages/django/urls/resolvers.py", line 526, in urlconf_module
    return import_module(self.urlconf_name)
  File "/usr/lib/python3.5/importlib/__init__.py", line 126, in import_module
    return _bootstrap._gcd_import(name[level:], package, level)
  File "<frozen importlib._bootstrap>", line 986, in _gcd_import
  File "<frozen importlib._bootstrap>", line 969, in _find_and_load
  File "<frozen importlib._bootstrap>", line 958, in _find_and_load_unlocked
  File "<frozen importlib._bootstrap>", line 673, in _load_unlocked
  File "<frozen importlib._bootstrap_external>", line 665, in exec_module
  File "<frozen importlib._bootstrap>", line 222, in _call_with_frames_removed
  File "./djaler/urls.py", line 20, in <module>
    from app_questions.views import IndexPage
  File "./app_questions/views.py", line 3, in <module>
    from backends.abc.basic_abc import basicViewAbstract
ImportError: No module named 'backends'
[pid: 12031|app: 0|req: 1/5] 127.0.0.1 () {44 vars in 912 bytes} [Wed Oct  3 18:20:38 2018] GET / => generated 112339 bytes in 56 msecs (HTTP/1.1 500) 4 headers in 130 bytes (1 switches on core 0)
Internal Server Error: /
Traceback (most recent call last):
  File "/home/adam/projects/virtualenvs/py352/lib/python3.5/site-packages/django/core/handlers/exception.py", line 34, in inner
    response = get_response(request)
  File "/home/adam/projects/virtualenvs/py352/lib/python3.5/site-packages/django/core/handlers/base.py", line 111, in _get_response
    resolver_match = resolver.resolve(request.path_info)
  File "/home/adam/projects/virtualenvs/py352/lib/python3.5/site-packages/django/urls/resolvers.py", line 491, in resolve
    for pattern in self.url_patterns:
  File "/home/adam/projects/virtualenvs/py352/lib/python3.5/site-packages/django/utils/functional.py", line 37, in __get__
    res = instance.__dict__[self.name] = self.func(instance)
  File "/home/adam/projects/virtualenvs/py352/lib/python3.5/site-packages/django/urls/resolvers.py", line 533, in url_patterns
    patterns = getattr(self.urlconf_module, "urlpatterns", self.urlconf_module)
  File "/home/adam/projects/virtualenvs/py352/lib/python3.5/site-packages/django/utils/functional.py", line 37, in __get__
    res = instance.__dict__[self.name] = self.func(instance)
  File "/home/adam/projects/virtualenvs/py352/lib/python3.5/site-packages/django/urls/resolvers.py", line 526, in urlconf_module
    return import_module(self.urlconf_name)
  File "/usr/lib/python3.5/importlib/__init__.py", line 126, in import_module
    return _bootstrap._gcd_import(name[level:], package, level)
  File "<frozen importlib._bootstrap>", line 986, in _gcd_import
  File "<frozen importlib._bootstrap>", line 969, in _find_and_load
  File "<frozen importlib._bootstrap>", line 958, in _find_and_load_unlocked
  File "<frozen importlib._bootstrap>", line 673, in _load_unlocked
  File "<frozen importlib._bootstrap_external>", line 665, in exec_module
  File "<frozen importlib._bootstrap>", line 222, in _call_with_frames_removed
  File "./djaler/urls.py", line 20, in <module>
    from app_questions.views import IndexPage
  File "./app_questions/views.py", line 3, in <module>
    from backends.abc.basic_abc import basicViewAbstract
ImportError: No module named 'backends'
[pid: 12030|app: 0|req: 1/6] 127.0.0.1 () {46 vars in 943 bytes} [Wed Oct  3 18:20:44 2018] GET / => generated 112474 bytes in 53 msecs (HTTP/1.1 500) 4 headers in 130 bytes (1 switches on core 0)
Internal Server Error: /
Traceback (most recent call last):
  File "/home/adam/projects/virtualenvs/py352/lib/python3.5/site-packages/django/core/handlers/exception.py", line 34, in inner
    response = get_response(request)
  File "/home/adam/projects/virtualenvs/py352/lib/python3.5/site-packages/django/core/handlers/base.py", line 111, in _get_response
    resolver_match = resolver.resolve(request.path_info)
  File "/home/adam/projects/virtualenvs/py352/lib/python3.5/site-packages/django/urls/resolvers.py", line 491, in resolve
    for pattern in self.url_patterns:
  File "/home/adam/projects/virtualenvs/py352/lib/python3.5/site-packages/django/utils/functional.py", line 37, in __get__
    res = instance.__dict__[self.name] = self.func(instance)
  File "/home/adam/projects/virtualenvs/py352/lib/python3.5/site-packages/django/urls/resolvers.py", line 533, in url_patterns
    patterns = getattr(self.urlconf_module, "urlpatterns", self.urlconf_module)
  File "/home/adam/projects/virtualenvs/py352/lib/python3.5/site-packages/django/utils/functional.py", line 37, in __get__
    res = instance.__dict__[self.name] = self.func(instance)
  File "/home/adam/projects/virtualenvs/py352/lib/python3.5/site-packages/django/urls/resolvers.py", line 526, in urlconf_module
    return import_module(self.urlconf_name)
  File "/usr/lib/python3.5/importlib/__init__.py", line 126, in import_module
    return _bootstrap._gcd_import(name[level:], package, level)
  File "<frozen importlib._bootstrap>", line 986, in _gcd_import
  File "<frozen importlib._bootstrap>", line 969, in _find_and_load
  File "<frozen importlib._bootstrap>", line 958, in _find_and_load_unlocked
  File "<frozen importlib._bootstrap>", line 673, in _load_unlocked
  File "<frozen importlib._bootstrap_external>", line 665, in exec_module
  File "<frozen importlib._bootstrap>", line 222, in _call_with_frames_removed
  File "./djaler/urls.py", line 25, in <module>
    path('questions/', include('app_questions.urls')),
  File "/home/adam/projects/virtualenvs/py352/lib/python3.5/site-packages/django/urls/conf.py", line 34, in include
    urlconf_module = import_module(urlconf_module)
  File "/usr/lib/python3.5/importlib/__init__.py", line 126, in import_module
    return _bootstrap._gcd_import(name[level:], package, level)
  File "<frozen importlib._bootstrap>", line 986, in _gcd_import
  File "<frozen importlib._bootstrap>", line 969, in _find_and_load
  File "<frozen importlib._bootstrap>", line 958, in _find_and_load_unlocked
  File "<frozen importlib._bootstrap>", line 673, in _load_unlocked
  File "<frozen importlib._bootstrap_external>", line 665, in exec_module
  File "<frozen importlib._bootstrap>", line 222, in _call_with_frames_removed
  File "./app_questions/urls.py", line 20, in <module>
    path(r'^(?P<question_slug>[A-Za-z0-9-]+)/$', QuestionPage.as_view(), name='question'),
NameError: name 'QuestionPage' is not defined
[pid: 12032|app: 0|req: 5/7] 127.0.0.1 () {46 vars in 943 bytes} [Wed Oct  3 18:22:52 2018] GET / => generated 138206 bytes in 59 msecs (HTTP/1.1 500) 4 headers in 130 bytes (1 switches on core 0)
Internal Server Error: /
Traceback (most recent call last):
  File "/home/adam/projects/virtualenvs/py352/lib/python3.5/site-packages/django/core/handlers/exception.py", line 34, in inner
    response = get_response(request)
  File "/home/adam/projects/virtualenvs/py352/lib/python3.5/site-packages/django/core/handlers/base.py", line 111, in _get_response
    resolver_match = resolver.resolve(request.path_info)
  File "/home/adam/projects/virtualenvs/py352/lib/python3.5/site-packages/django/urls/resolvers.py", line 491, in resolve
    for pattern in self.url_patterns:
  File "/home/adam/projects/virtualenvs/py352/lib/python3.5/site-packages/django/utils/functional.py", line 37, in __get__
    res = instance.__dict__[self.name] = self.func(instance)
  File "/home/adam/projects/virtualenvs/py352/lib/python3.5/site-packages/django/urls/resolvers.py", line 533, in url_patterns
    patterns = getattr(self.urlconf_module, "urlpatterns", self.urlconf_module)
  File "/home/adam/projects/virtualenvs/py352/lib/python3.5/site-packages/django/utils/functional.py", line 37, in __get__
    res = instance.__dict__[self.name] = self.func(instance)
  File "/home/adam/projects/virtualenvs/py352/lib/python3.5/site-packages/django/urls/resolvers.py", line 526, in urlconf_module
    return import_module(self.urlconf_name)
  File "/usr/lib/python3.5/importlib/__init__.py", line 126, in import_module
    return _bootstrap._gcd_import(name[level:], package, level)
  File "<frozen importlib._bootstrap>", line 986, in _gcd_import
  File "<frozen importlib._bootstrap>", line 969, in _find_and_load
  File "<frozen importlib._bootstrap>", line 958, in _find_and_load_unlocked
  File "<frozen importlib._bootstrap>", line 673, in _load_unlocked
  File "<frozen importlib._bootstrap_external>", line 665, in exec_module
  File "<frozen importlib._bootstrap>", line 222, in _call_with_frames_removed
  File "./djaler/urls.py", line 25, in <module>
    path('questions/', include('app_questions.urls')),
  File "/home/adam/projects/virtualenvs/py352/lib/python3.5/site-packages/django/urls/conf.py", line 34, in include
    urlconf_module = import_module(urlconf_module)
  File "/usr/lib/python3.5/importlib/__init__.py", line 126, in import_module
    return _bootstrap._gcd_import(name[level:], package, level)
  File "<frozen importlib._bootstrap>", line 986, in _gcd_import
  File "<frozen importlib._bootstrap>", line 969, in _find_and_load
  File "<frozen importlib._bootstrap>", line 958, in _find_and_load_unlocked
  File "<frozen importlib._bootstrap>", line 673, in _load_unlocked
  File "<frozen importlib._bootstrap_external>", line 665, in exec_module
  File "<frozen importlib._bootstrap>", line 222, in _call_with_frames_removed
  File "./app_questions/urls.py", line 20, in <module>
    path(r'^(?P<question_slug>[A-Za-z0-9-]+)/$', QuestionPage.as_view(), name='question'),
NameError: name 'QuestionPage' is not defined
[pid: 12029|app: 0|req: 1/8] 127.0.0.1 () {46 vars in 943 bytes} [Wed Oct  3 18:22:53 2018] GET / => generated 138206 bytes in 69 msecs (HTTP/1.1 500) 4 headers in 130 bytes (1 switches on core 0)
Internal Server Error: /
Traceback (most recent call last):
  File "/home/adam/projects/virtualenvs/py352/lib/python3.5/site-packages/django/core/handlers/exception.py", line 34, in inner
    response = get_response(request)
  File "/home/adam/projects/virtualenvs/py352/lib/python3.5/site-packages/django/core/handlers/base.py", line 111, in _get_response
    resolver_match = resolver.resolve(request.path_info)
  File "/home/adam/projects/virtualenvs/py352/lib/python3.5/site-packages/django/urls/resolvers.py", line 491, in resolve
    for pattern in self.url_patterns:
  File "/home/adam/projects/virtualenvs/py352/lib/python3.5/site-packages/django/utils/functional.py", line 37, in __get__
    res = instance.__dict__[self.name] = self.func(instance)
  File "/home/adam/projects/virtualenvs/py352/lib/python3.5/site-packages/django/urls/resolvers.py", line 533, in url_patterns
    patterns = getattr(self.urlconf_module, "urlpatterns", self.urlconf_module)
  File "/home/adam/projects/virtualenvs/py352/lib/python3.5/site-packages/django/utils/functional.py", line 37, in __get__
    res = instance.__dict__[self.name] = self.func(instance)
  File "/home/adam/projects/virtualenvs/py352/lib/python3.5/site-packages/django/urls/resolvers.py", line 526, in urlconf_module
    return import_module(self.urlconf_name)
  File "/usr/lib/python3.5/importlib/__init__.py", line 126, in import_module
    return _bootstrap._gcd_import(name[level:], package, level)
  File "<frozen importlib._bootstrap>", line 986, in _gcd_import
  File "<frozen importlib._bootstrap>", line 969, in _find_and_load
  File "<frozen importlib._bootstrap>", line 958, in _find_and_load_unlocked
  File "<frozen importlib._bootstrap>", line 673, in _load_unlocked
  File "<frozen importlib._bootstrap_external>", line 665, in exec_module
  File "<frozen importlib._bootstrap>", line 222, in _call_with_frames_removed
  File "./djaler/urls.py", line 25, in <module>
    path('questions/', include('app_questions.urls')),
  File "/home/adam/projects/virtualenvs/py352/lib/python3.5/site-packages/django/urls/conf.py", line 34, in include
    urlconf_module = import_module(urlconf_module)
  File "/usr/lib/python3.5/importlib/__init__.py", line 126, in import_module
    return _bootstrap._gcd_import(name[level:], package, level)
  File "<frozen importlib._bootstrap>", line 986, in _gcd_import
  File "<frozen importlib._bootstrap>", line 969, in _find_and_load
  File "<frozen importlib._bootstrap>", line 958, in _find_and_load_unlocked
  File "<frozen importlib._bootstrap>", line 673, in _load_unlocked
  File "<frozen importlib._bootstrap_external>", line 665, in exec_module
  File "<frozen importlib._bootstrap>", line 222, in _call_with_frames_removed
  File "./app_questions/urls.py", line 20, in <module>
    path(r'^(?P<question_slug>[A-Za-z0-9-]+)/$', IndexPage.as_view(), name='question'),
NameError: name 'IndexPage' is not defined
[pid: 12032|app: 0|req: 6/9] 127.0.0.1 () {46 vars in 943 bytes} [Wed Oct  3 18:23:13 2018] GET / => generated 138188 bytes in 58 msecs (HTTP/1.1 500) 4 headers in 130 bytes (1 switches on core 0)
Internal Server Error: /
Traceback (most recent call last):
  File "/home/adam/projects/virtualenvs/py352/lib/python3.5/site-packages/django/core/handlers/exception.py", line 34, in inner
    response = get_response(request)
  File "/home/adam/projects/virtualenvs/py352/lib/python3.5/site-packages/django/core/handlers/base.py", line 111, in _get_response
    resolver_match = resolver.resolve(request.path_info)
  File "/home/adam/projects/virtualenvs/py352/lib/python3.5/site-packages/django/urls/resolvers.py", line 491, in resolve
    for pattern in self.url_patterns:
  File "/home/adam/projects/virtualenvs/py352/lib/python3.5/site-packages/django/utils/functional.py", line 37, in __get__
    res = instance.__dict__[self.name] = self.func(instance)
  File "/home/adam/projects/virtualenvs/py352/lib/python3.5/site-packages/django/urls/resolvers.py", line 533, in url_patterns
    patterns = getattr(self.urlconf_module, "urlpatterns", self.urlconf_module)
  File "/home/adam/projects/virtualenvs/py352/lib/python3.5/site-packages/django/utils/functional.py", line 37, in __get__
    res = instance.__dict__[self.name] = self.func(instance)
  File "/home/adam/projects/virtualenvs/py352/lib/python3.5/site-packages/django/urls/resolvers.py", line 526, in urlconf_module
    return import_module(self.urlconf_name)
  File "/usr/lib/python3.5/importlib/__init__.py", line 126, in import_module
    return _bootstrap._gcd_import(name[level:], package, level)
  File "<frozen importlib._bootstrap>", line 986, in _gcd_import
  File "<frozen importlib._bootstrap>", line 969, in _find_and_load
  File "<frozen importlib._bootstrap>", line 958, in _find_and_load_unlocked
  File "<frozen importlib._bootstrap>", line 673, in _load_unlocked
  File "<frozen importlib._bootstrap_external>", line 665, in exec_module
  File "<frozen importlib._bootstrap>", line 222, in _call_with_frames_removed
  File "./djaler/urls.py", line 25, in <module>
    path('questions/', include('app_questions.urls')),
  File "/home/adam/projects/virtualenvs/py352/lib/python3.5/site-packages/django/urls/conf.py", line 34, in include
    urlconf_module = import_module(urlconf_module)
  File "/usr/lib/python3.5/importlib/__init__.py", line 126, in import_module
    return _bootstrap._gcd_import(name[level:], package, level)
  File "<frozen importlib._bootstrap>", line 986, in _gcd_import
  File "<frozen importlib._bootstrap>", line 969, in _find_and_load
  File "<frozen importlib._bootstrap>", line 958, in _find_and_load_unlocked
  File "<frozen importlib._bootstrap>", line 673, in _load_unlocked
  File "<frozen importlib._bootstrap_external>", line 665, in exec_module
  File "<frozen importlib._bootstrap>", line 222, in _call_with_frames_removed
  File "./app_questions/urls.py", line 20, in <module>
    path(r'^(?P<question_slug>[A-Za-z0-9-]+)/$', IndexPage.as_view(), name='question'),
NameError: name 'IndexPage' is not defined
[pid: 12030|app: 0|req: 2/10] 127.0.0.1 () {46 vars in 943 bytes} [Wed Oct  3 18:23:14 2018] GET / => generated 138188 bytes in 62 msecs (HTTP/1.1 500) 4 headers in 130 bytes (1 switches on core 0)
Internal Server Error: /
Traceback (most recent call last):
  File "/home/adam/projects/virtualenvs/py352/lib/python3.5/site-packages/django/core/handlers/exception.py", line 34, in inner
    response = get_response(request)
  File "/home/adam/projects/virtualenvs/py352/lib/python3.5/site-packages/django/core/handlers/base.py", line 111, in _get_response
    resolver_match = resolver.resolve(request.path_info)
  File "/home/adam/projects/virtualenvs/py352/lib/python3.5/site-packages/django/urls/resolvers.py", line 491, in resolve
    for pattern in self.url_patterns:
  File "/home/adam/projects/virtualenvs/py352/lib/python3.5/site-packages/django/utils/functional.py", line 37, in __get__
    res = instance.__dict__[self.name] = self.func(instance)
  File "/home/adam/projects/virtualenvs/py352/lib/python3.5/site-packages/django/urls/resolvers.py", line 533, in url_patterns
    patterns = getattr(self.urlconf_module, "urlpatterns", self.urlconf_module)
  File "/home/adam/projects/virtualenvs/py352/lib/python3.5/site-packages/django/utils/functional.py", line 37, in __get__
    res = instance.__dict__[self.name] = self.func(instance)
  File "/home/adam/projects/virtualenvs/py352/lib/python3.5/site-packages/django/urls/resolvers.py", line 526, in urlconf_module
    return import_module(self.urlconf_name)
  File "/usr/lib/python3.5/importlib/__init__.py", line 126, in import_module
    return _bootstrap._gcd_import(name[level:], package, level)
  File "<frozen importlib._bootstrap>", line 986, in _gcd_import
  File "<frozen importlib._bootstrap>", line 969, in _find_and_load
  File "<frozen importlib._bootstrap>", line 958, in _find_and_load_unlocked
  File "<frozen importlib._bootstrap>", line 673, in _load_unlocked
  File "<frozen importlib._bootstrap_external>", line 665, in exec_module
  File "<frozen importlib._bootstrap>", line 222, in _call_with_frames_removed
  File "./djaler/urls.py", line 25, in <module>
    path('questions/', include('app_questions.urls')),
  File "/home/adam/projects/virtualenvs/py352/lib/python3.5/site-packages/django/urls/conf.py", line 34, in include
    urlconf_module = import_module(urlconf_module)
  File "/usr/lib/python3.5/importlib/__init__.py", line 126, in import_module
    return _bootstrap._gcd_import(name[level:], package, level)
  File "<frozen importlib._bootstrap>", line 986, in _gcd_import
  File "<frozen importlib._bootstrap>", line 969, in _find_and_load
  File "<frozen importlib._bootstrap>", line 958, in _find_and_load_unlocked
  File "<frozen importlib._bootstrap>", line 673, in _load_unlocked
  File "<frozen importlib._bootstrap_external>", line 665, in exec_module
  File "<frozen importlib._bootstrap>", line 222, in _call_with_frames_removed
  File "./app_questions/urls.py", line 20, in <module>
    path(r'^(?P<question_slug>[A-Za-z0-9-]+)/$', IndexPage.as_view(), name='question'),
NameError: name 'IndexPage' is not defined
[pid: 12032|app: 0|req: 7/11] 127.0.0.1 () {46 vars in 943 bytes} [Wed Oct  3 18:23:14 2018] GET / => generated 138188 bytes in 57 msecs (HTTP/1.1 500) 4 headers in 130 bytes (1 switches on core 0)
Not Found: /
[pid: 12032|app: 0|req: 8/12] 127.0.0.1 () {46 vars in 943 bytes} [Wed Oct  3 18:25:04 2018] GET / => generated 2150 bytes in 5 msecs (HTTP/1.1 404) 3 headers in 102 bytes (1 switches on core 0)
Not Found: /questions/
[pid: 12029|app: 0|req: 2/13] 127.0.0.1 () {44 vars in 932 bytes} [Wed Oct  3 18:25:15 2018] GET /questions/ => generated 2303 bytes in 5 msecs (HTTP/1.1 404) 3 headers in 102 bytes (1 switches on core 0)
Not Found: /
[pid: 12029|app: 0|req: 3/14] 127.0.0.1 () {46 vars in 943 bytes} [Wed Oct  3 18:25:53 2018] GET / => generated 2150 bytes in 2 msecs (HTTP/1.1 404) 3 headers in 102 bytes (1 switches on core 0)
Not Found: /
[pid: 12032|app: 0|req: 9/15] 127.0.0.1 () {46 vars in 943 bytes} [Wed Oct  3 18:25:54 2018] GET / => generated 2150 bytes in 3 msecs (HTTP/1.1 404) 3 headers in 102 bytes (1 switches on core 0)
Not Found: /
[pid: 12032|app: 0|req: 10/16] 127.0.0.1 () {46 vars in 943 bytes} [Wed Oct  3 18:25:55 2018] GET / => generated 2150 bytes in 2 msecs (HTTP/1.1 404) 3 headers in 102 bytes (1 switches on core 0)
Not Found: /
[pid: 12032|app: 0|req: 11/17] 127.0.0.1 () {46 vars in 943 bytes} [Wed Oct  3 18:25:55 2018] GET / => generated 2150 bytes in 3 msecs (HTTP/1.1 404) 3 headers in 102 bytes (1 switches on core 0)
Not Found: /
[pid: 12032|app: 0|req: 12/18] 127.0.0.1 () {46 vars in 943 bytes} [Wed Oct  3 18:25:55 2018] GET / => generated 2150 bytes in 2 msecs (HTTP/1.1 404) 3 headers in 102 bytes (1 switches on core 0)
Internal Server Error: /
Traceback (most recent call last):
  File "/home/adam/projects/virtualenvs/py352/lib/python3.5/site-packages/django/core/handlers/exception.py", line 34, in inner
    response = get_response(request)
  File "/home/adam/projects/virtualenvs/py352/lib/python3.5/site-packages/django/core/handlers/base.py", line 126, in _get_response
    response = self.process_exception_by_middleware(e, request)
  File "/home/adam/projects/virtualenvs/py352/lib/python3.5/site-packages/django/core/handlers/base.py", line 124, in _get_response
    response = wrapped_callback(request, *callback_args, **callback_kwargs)
  File "/home/adam/projects/virtualenvs/py352/lib/python3.5/site-packages/django/views/generic/base.py", line 68, in view
    return self.dispatch(request, *args, **kwargs)
  File "/home/adam/projects/virtualenvs/py352/lib/python3.5/site-packages/django/views/generic/base.py", line 88, in dispatch
    return handler(request, *args, **kwargs)
  File "/home/adam/projects/virtualenvs/py352/lib/python3.5/site-packages/django/views/generic/list.py", line 142, in get
    self.object_list = self.get_queryset()
  File "./app_questions/views.py", line 18, in get_queryset
    self.questions = Questions.objects.select_related("extuser__username").values("id", "title", "text", "date_time", "slug", "extuser__username", "category__name").filter(hided=False, published=True).order_by('?')[:3]
NameError: name 'Questions' is not defined
[pid: 12031|app: 0|req: 2/19] 127.0.0.1 () {46 vars in 943 bytes} [Wed Oct  3 18:25:55 2018] GET / => generated 72971 bytes in 73 msecs (HTTP/1.1 500) 4 headers in 129 bytes (1 switches on core 0)
Internal Server Error: /
Traceback (most recent call last):
  File "/home/adam/projects/virtualenvs/py352/lib/python3.5/site-packages/django/core/handlers/exception.py", line 34, in inner
    response = get_response(request)
  File "/home/adam/projects/virtualenvs/py352/lib/python3.5/site-packages/django/core/handlers/base.py", line 126, in _get_response
    response = self.process_exception_by_middleware(e, request)
  File "/home/adam/projects/virtualenvs/py352/lib/python3.5/site-packages/django/core/handlers/base.py", line 124, in _get_response
    response = wrapped_callback(request, *callback_args, **callback_kwargs)
  File "/home/adam/projects/virtualenvs/py352/lib/python3.5/site-packages/django/views/generic/base.py", line 68, in view
    return self.dispatch(request, *args, **kwargs)
  File "/home/adam/projects/virtualenvs/py352/lib/python3.5/site-packages/django/views/generic/base.py", line 88, in dispatch
    return handler(request, *args, **kwargs)
  File "/home/adam/projects/virtualenvs/py352/lib/python3.5/site-packages/django/views/generic/list.py", line 142, in get
    self.object_list = self.get_queryset()
  File "./app_questions/views.py", line 18, in get_queryset
    self.questions = Questions.objects.select_related("extuser__username").values("id", "title", "text", "date_time", "slug", "extuser__username", "category__name").filter(hided=False, published=True).order_by('?')[:3]
NameError: name 'Questions' is not defined
[pid: 12031|app: 0|req: 3/20] 127.0.0.1 () {46 vars in 943 bytes} [Wed Oct  3 18:26:01 2018] GET / => generated 72971 bytes in 28 msecs (HTTP/1.1 500) 4 headers in 129 bytes (1 switches on core 0)
Internal Server Error: /
Traceback (most recent call last):
  File "/home/adam/projects/virtualenvs/py352/lib/python3.5/site-packages/django/core/handlers/exception.py", line 34, in inner
    response = get_response(request)
  File "/home/adam/projects/virtualenvs/py352/lib/python3.5/site-packages/django/core/handlers/base.py", line 126, in _get_response
    response = self.process_exception_by_middleware(e, request)
  File "/home/adam/projects/virtualenvs/py352/lib/python3.5/site-packages/django/core/handlers/base.py", line 124, in _get_response
    response = wrapped_callback(request, *callback_args, **callback_kwargs)
  File "/home/adam/projects/virtualenvs/py352/lib/python3.5/site-packages/django/views/generic/base.py", line 68, in view
    return self.dispatch(request, *args, **kwargs)
  File "/home/adam/projects/virtualenvs/py352/lib/python3.5/site-packages/django/views/generic/base.py", line 88, in dispatch
    return handler(request, *args, **kwargs)
  File "/home/adam/projects/virtualenvs/py352/lib/python3.5/site-packages/django/views/generic/list.py", line 142, in get
    self.object_list = self.get_queryset()
  File "./app_questions/views.py", line 18, in get_queryset
    self.questions = Questions.objects.select_related("extuser__username").values("id", "title", "text", "date_time", "slug", "extuser__username", "category__name").filter(hided=False, published=True).order_by('?')[:3]
NameError: name 'Questions' is not defined
[pid: 12030|app: 0|req: 3/21] 127.0.0.1 () {46 vars in 943 bytes} [Wed Oct  3 18:26:01 2018] GET / => generated 72971 bytes in 32 msecs (HTTP/1.1 500) 4 headers in 129 bytes (1 switches on core 0)
